[2024-09-29T09:13:13.031+0000] {local_task_job_runner.py:120} INFO - ::group::Pre task execution logs
[2024-09-29T09:13:13.076+0000] {taskinstance.py:2073} INFO - Dependencies all met for dep_context=non-requeueable deps ti=<TaskInstance: etl.gcs_to_bq_fact scheduled__2024-06-06T00:00:00+00:00 [queued]>
[2024-09-29T09:13:13.111+0000] {taskinstance.py:2073} INFO - Dependencies all met for dep_context=requeueable deps ti=<TaskInstance: etl.gcs_to_bq_fact scheduled__2024-06-06T00:00:00+00:00 [queued]>
[2024-09-29T09:13:13.112+0000] {taskinstance.py:2303} INFO - Starting attempt 1 of 1
[2024-09-29T09:13:13.220+0000] {taskinstance.py:2327} INFO - Executing <Task(GCSToBigQueryOperator): gcs_to_bq_fact> on 2024-06-06 00:00:00+00:00
[2024-09-29T09:13:13.301+0000] {logging_mixin.py:188} WARNING - /home/***/.local/lib/python3.12/site-packages/***/task/task_runner/standard_task_runner.py:61 DeprecationWarning: This process (pid=33788) is multi-threaded, use of fork() may lead to deadlocks in the child.
[2024-09-29T09:13:13.302+0000] {standard_task_runner.py:63} INFO - Started process 33879 to run task
[2024-09-29T09:13:13.294+0000] {standard_task_runner.py:90} INFO - Running: ['***', 'tasks', 'run', 'etl', 'gcs_to_bq_fact', 'scheduled__2024-06-06T00:00:00+00:00', '--job-id', '646', '--raw', '--subdir', 'DAGS_FOLDER/etl.py', '--cfg-path', '/tmp/tmph3ty2bvq']
[2024-09-29T09:13:13.305+0000] {standard_task_runner.py:91} INFO - Job 646: Subtask gcs_to_bq_fact
[2024-09-29T09:13:13.522+0000] {task_command.py:426} INFO - Running <TaskInstance: etl.gcs_to_bq_fact scheduled__2024-06-06T00:00:00+00:00 [running]> on host 71321b93f95e
[2024-09-29T09:13:13.939+0000] {taskinstance.py:2644} INFO - Exporting env vars: AIRFLOW_CTX_DAG_OWNER='***' AIRFLOW_CTX_DAG_ID='etl' AIRFLOW_CTX_TASK_ID='gcs_to_bq_fact' AIRFLOW_CTX_EXECUTION_DATE='2024-06-06T00:00:00+00:00' AIRFLOW_CTX_TRY_NUMBER='1' AIRFLOW_CTX_DAG_RUN_ID='scheduled__2024-06-06T00:00:00+00:00'
[2024-09-29T09:13:13.941+0000] {taskinstance.py:430} INFO - ::endgroup::
[2024-09-29T09:13:13.981+0000] {connection.py:274} WARNING - Connection schemes (type: google_cloud_platform) shall not contain '_' according to RFC3986.
[2024-09-29T09:13:14.015+0000] {base.py:84} INFO - Using connection ID 'my_gcp_conn' for task execution.
[2024-09-29T09:13:14.031+0000] {gcs_to_bigquery.py:379} INFO - Using existing BigQuery table for storing data...
[2024-09-29T09:13:14.299+0000] {bigquery.py:2328} INFO - Project is not included in destination_project_dataset_table: finalproject_data.fact; using project "madt-finalproject"
[2024-09-29T09:13:14.300+0000] {gcs_to_bigquery.py:383} INFO - Executing: {'load': {'autodetect': True, 'createDisposition': 'CREATE_IF_NEEDED', 'destinationTable': {'projectId': 'madt-finalproject', 'datasetId': 'finalproject_data', 'tableId': 'fact'}, 'sourceFormat': 'CSV', 'sourceUris': ['gs://storage-madt-finalproject/fact.csv'], 'writeDisposition': 'WRITE_TRUNCATE', 'ignoreUnknownValues': False, 'skipLeadingRows': None, 'fieldDelimiter': ',', 'quote': None, 'allowQuotedNewlines': False, 'encoding': 'UTF-8'}}
[2024-09-29T09:13:14.322+0000] {bigquery.py:1613} INFO - Inserting job ***_etl_gcs_to_bq_fact_2024_06_06T00_00_00_00_00_00f9ecf50e0bff14b5fff35fdacaed84
[2024-09-29T09:13:17.297+0000] {taskinstance.py:441} INFO - ::group::Post task execution logs
[2024-09-29T09:13:17.298+0000] {taskinstance.py:2890} ERROR - Task failed with exception
Traceback (most recent call last):
  File "/home/airflow/.local/lib/python3.12/site-packages/airflow/models/taskinstance.py", line 465, in _execute_task
    result = _execute_callable(context=context, **execute_callable_kwargs)
             ^^^^^^^^^^^^^^^^^^^^^^^^^^^^^^^^^^^^^^^^^^^^^^^^^^^^^^^^^^^^^
  File "/home/airflow/.local/lib/python3.12/site-packages/airflow/models/taskinstance.py", line 432, in _execute_callable
    return execute_callable(context=context, **execute_callable_kwargs)
           ^^^^^^^^^^^^^^^^^^^^^^^^^^^^^^^^^^^^^^^^^^^^^^^^^^^^^^^^^^^^
  File "/home/airflow/.local/lib/python3.12/site-packages/airflow/models/baseoperator.py", line 400, in wrapper
    return func(self, *args, **kwargs)
           ^^^^^^^^^^^^^^^^^^^^^^^^^^^
  File "/home/airflow/.local/lib/python3.12/site-packages/airflow/providers/google/cloud/transfers/gcs_to_bigquery.py", line 444, in execute
    job.result(timeout=self.result_timeout, retry=self.result_retry)
  File "/home/airflow/.local/lib/python3.12/site-packages/google/cloud/bigquery/job/base.py", line 971, in result
    return super(_AsyncJob, self).result(timeout=timeout, **kwargs)
           ^^^^^^^^^^^^^^^^^^^^^^^^^^^^^^^^^^^^^^^^^^^^^^^^^^^^^^^^
  File "/home/airflow/.local/lib/python3.12/site-packages/google/api_core/future/polling.py", line 261, in result
    raise self._exception
google.api_core.exceptions.BadRequest: 400 Error while reading data, error message: CSV processing encountered too many errors, giving up. Rows: 44153; errors: 2; max bad: 0; error percent: 0; reason: invalid, message: Error while reading data, error message: CSV processing encountered too many errors, giving up. Rows: 44153; errors: 2; max bad: 0; error percent: 0; reason: invalid, location: gs://storage-madt-finalproject/fact.csv, message: Error while reading data, error message: Unable to parse; line_number: 44153 byte_offset_to_start_of_line: 2585949 column_index: 0 column_name: "detail_id" column_type: INT64 value: "(blank)" File: gs://storage-madt-finalproject/fact.csv; reason: invalid, location: gs://storage-madt-finalproject/fact.csv, message: Error while reading data, error message: Unable to parse; line_number: 44154 byte_offset_to_start_of_line: 2586014 column_index: 0 column_name: "detail_id" column_type: INT64 value: "Grand Total" File: gs://storage-madt-finalproject/fact.csv
[2024-09-29T09:13:17.344+0000] {taskinstance.py:1205} INFO - Marking task as FAILED. dag_id=etl, task_id=gcs_to_bq_fact, execution_date=20240606T000000, start_date=20240929T091313, end_date=20240929T091317
[2024-09-29T09:13:17.423+0000] {standard_task_runner.py:110} ERROR - Failed to execute job 646 for task gcs_to_bq_fact (400 Error while reading data, error message: CSV processing encountered too many errors, giving up. Rows: 44153; errors: 2; max bad: 0; error percent: 0; reason: invalid, message: Error while reading data, error message: CSV processing encountered too many errors, giving up. Rows: 44153; errors: 2; max bad: 0; error percent: 0; reason: invalid, location: gs://storage-madt-finalproject/fact.csv, message: Error while reading data, error message: Unable to parse; line_number: 44153 byte_offset_to_start_of_line: 2585949 column_index: 0 column_name: "detail_id" column_type: INT64 value: "(blank)" File: gs://storage-madt-finalproject/fact.csv; reason: invalid, location: gs://storage-madt-finalproject/fact.csv, message: Error while reading data, error message: Unable to parse; line_number: 44154 byte_offset_to_start_of_line: 2586014 column_index: 0 column_name: "detail_id" column_type: INT64 value: "Grand Total" File: gs://storage-madt-finalproject/fact.csv; 33879)
[2024-09-29T09:13:17.526+0000] {local_task_job_runner.py:240} INFO - Task exited with return code 1
[2024-09-29T09:13:17.948+0000] {taskinstance.py:3482} INFO - 0 downstream tasks scheduled from follow-on schedule check
[2024-09-29T09:13:17.966+0000] {local_task_job_runner.py:222} INFO - ::endgroup::
